2025-04-25 16:12:34.906 ERROR (Recorder) [homeassistant.components.recorder.core] Error during connection setup: (retrying in 3 seconds)
Traceback (most recent call last):
  File "/usr/src/homeassistant/homeassistant/components/recorder/core.py", line 927, in _setup_recorder
    self._setup_connection()
    ~~~~~~~~~~~~~~~~~~~~~~^^
  File "/usr/src/homeassistant/homeassistant/components/recorder/core.py", line 1437, in _setup_connection
    self.engine = create_engine(self.db_url, **kwargs, future=True)
                  ~~~~~~~~~~~~~^^^^^^^^^^^^^^^^^^^^^^^^^^^^^^^^^^^^
  File "<string>", line 2, in create_engine
  File "/usr/local/lib/python3.13/site-packages/sqlalchemy/util/deprecations.py", line 281, in warned
    return fn(*args, **kwargs)  # type: ignore[no-any-return]
  File "/usr/local/lib/python3.13/site-packages/sqlalchemy/engine/create.py", line 553, in create_engine
    entrypoint = u._get_entrypoint()
  File "/usr/local/lib/python3.13/site-packages/sqlalchemy/engine/url.py", line 772, in _get_entrypoint
    cls = registry.load(name)
  File "/usr/local/lib/python3.13/site-packages/sqlalchemy/util/langhelpers.py", line 375, in load
    raise exc.NoSuchModuleError(
        "Can't load plugin: %s:%s" % (self.group, name)
    )
sqlalchemy.exc.NoSuchModuleError: Can't load plugin: sqlalchemy.dialects:influxdb
2025-04-25 16:12:38.026 ERROR (Recorder) [homeassistant.components.recorder.core] Error during connection setup: (retrying in 3 seconds)
Traceback (most recent call last):
  File "/usr/src/homeassistant/homeassistant/components/recorder/core.py", line 927, in _setup_recorder
    self._setup_connection()
    ~~~~~~~~~~~~~~~~~~~~~~^^
  File "/usr/src/homeassistant/homeassistant/components/recorder/core.py", line 1437, in _setup_connection
    self.engine = create_engine(self.db_url, **kwargs, future=True)
                  ~~~~~~~~~~~~~^^^^^^^^^^^^^^^^^^^^^^^^^^^^^^^^^^^^
  File "<string>", line 2, in create_engine
  File "/usr/local/lib/python3.13/site-packages/sqlalchemy/util/deprecations.py", line 281, in warned
    return fn(*args, **kwargs)  # type: ignore[no-any-return]
  File "/usr/local/lib/python3.13/site-packages/sqlalchemy/engine/create.py", line 553, in create_engine
    entrypoint = u._get_entrypoint()
  File "/usr/local/lib/python3.13/site-packages/sqlalchemy/engine/url.py", line 772, in _get_entrypoint
    cls = registry.load(name)
  File "/usr/local/lib/python3.13/site-packages/sqlalchemy/util/langhelpers.py", line 375, in load
    raise exc.NoSuchModuleError(
        "Can't load plugin: %s:%s" % (self.group, name)
    )
sqlalchemy.exc.NoSuchModuleError: Can't load plugin: sqlalchemy.dialects:influxdb
2025-04-25 16:12:41.143 ERROR (Recorder) [homeassistant.components.recorder.core] Error during connection setup: (retrying in 3 seconds)
Traceback (most recent call last):
  File "/usr/src/homeassistant/homeassistant/components/recorder/core.py", line 927, in _setup_recorder
    self._setup_connection()
    ~~~~~~~~~~~~~~~~~~~~~~^^
  File "/usr/src/homeassistant/homeassistant/components/recorder/core.py", line 1437, in _setup_connection
    self.engine = create_engine(self.db_url, **kwargs, future=True)
                  ~~~~~~~~~~~~~^^^^^^^^^^^^^^^^^^^^^^^^^^^^^^^^^^^^
  File "<string>", line 2, in create_engine
  File "/usr/local/lib/python3.13/site-packages/sqlalchemy/util/deprecations.py", line 281, in warned
    return fn(*args, **kwargs)  # type: ignore[no-any-return]
  File "/usr/local/lib/python3.13/site-packages/sqlalchemy/engine/create.py", line 553, in create_engine
    entrypoint = u._get_entrypoint()
  File "/usr/local/lib/python3.13/site-packages/sqlalchemy/engine/url.py", line 772, in _get_entrypoint
    cls = registry.load(name)
  File "/usr/local/lib/python3.13/site-packages/sqlalchemy/util/langhelpers.py", line 375, in load
    raise exc.NoSuchModuleError(
        "Can't load plugin: %s:%s" % (self.group, name)
    )
sqlalchemy.exc.NoSuchModuleError: Can't load plugin: sqlalchemy.dialects:influxdb
2025-04-25 16:12:44.263 ERROR (Recorder) [homeassistant.components.recorder.core] Error during connection setup: (retrying in 3 seconds)
Traceback (most recent call last):
  File "/usr/src/homeassistant/homeassistant/components/recorder/core.py", line 927, in _setup_recorder
    self._setup_connection()
    ~~~~~~~~~~~~~~~~~~~~~~^^
  File "/usr/src/homeassistant/homeassistant/components/recorder/core.py", line 1437, in _setup_connection
    self.engine = create_engine(self.db_url, **kwargs, future=True)
                  ~~~~~~~~~~~~~^^^^^^^^^^^^^^^^^^^^^^^^^^^^^^^^^^^^
  File "<string>", line 2, in create_engine
  File "/usr/local/lib/python3.13/site-packages/sqlalchemy/util/deprecations.py", line 281, in warned
    return fn(*args, **kwargs)  # type: ignore[no-any-return]
  File "/usr/local/lib/python3.13/site-packages/sqlalchemy/engine/create.py", line 553, in create_engine
    entrypoint = u._get_entrypoint()
  File "/usr/local/lib/python3.13/site-packages/sqlalchemy/engine/url.py", line 772, in _get_entrypoint
    cls = registry.load(name)
  File "/usr/local/lib/python3.13/site-packages/sqlalchemy/util/langhelpers.py", line 375, in load
    raise exc.NoSuchModuleError(
        "Can't load plugin: %s:%s" % (self.group, name)
    )
sqlalchemy.exc.NoSuchModuleError: Can't load plugin: sqlalchemy.dialects:influxdb
2025-04-25 16:12:44.743 WARNING (MainThread) [homeassistant.setup] Setup of recorder is taking over 10 seconds.
2025-04-25 16:12:47.395 ERROR (Recorder) [homeassistant.components.recorder.core] Error during connection setup: (retrying in 3 seconds)
Traceback (most recent call last):
  File "/usr/src/homeassistant/homeassistant/components/recorder/core.py", line 927, in _setup_recorder
    self._setup_connection()
    ~~~~~~~~~~~~~~~~~~~~~~^^
  File "/usr/src/homeassistant/homeassistant/components/recorder/core.py", line 1437, in _setup_connection
    self.engine = create_engine(self.db_url, **kwargs, future=True)
                  ~~~~~~~~~~~~~^^^^^^^^^^^^^^^^^^^^^^^^^^^^^^^^^^^^
  File "<string>", line 2, in create_engine
  File "/usr/local/lib/python3.13/site-packages/sqlalchemy/util/deprecations.py", line 281, in warned
    return fn(*args, **kwargs)  # type: ignore[no-any-return]
  File "/usr/local/lib/python3.13/site-packages/sqlalchemy/engine/create.py", line 553, in create_engine
    entrypoint = u._get_entrypoint()
  File "/usr/local/lib/python3.13/site-packages/sqlalchemy/engine/url.py", line 772, in _get_entrypoint
    cls = registry.load(name)
  File "/usr/local/lib/python3.13/site-packages/sqlalchemy/util/langhelpers.py", line 375, in load
    raise exc.NoSuchModuleError(
        "Can't load plugin: %s:%s" % (self.group, name)
    )
sqlalchemy.exc.NoSuchModuleError: Can't load plugin: sqlalchemy.dialects:influxdb
2025-04-25 16:12:50.513 ERROR (Recorder) [homeassistant.components.recorder.core] Error during connection setup: (retrying in 3 seconds)
Traceback (most recent call last):
  File "/usr/src/homeassistant/homeassistant/components/recorder/core.py", line 927, in _setup_recorder
    self._setup_connection()
    ~~~~~~~~~~~~~~~~~~~~~~^^
  File "/usr/src/homeassistant/homeassistant/components/recorder/core.py", line 1437, in _setup_connection
    self.engine = create_engine(self.db_url, **kwargs, future=True)
                  ~~~~~~~~~~~~~^^^^^^^^^^^^^^^^^^^^^^^^^^^^^^^^^^^^
  File "<string>", line 2, in create_engine
  File "/usr/local/lib/python3.13/site-packages/sqlalchemy/util/deprecations.py", line 281, in warned
    return fn(*args, **kwargs)  # type: ignore[no-any-return]
  File "/usr/local/lib/python3.13/site-packages/sqlalchemy/engine/create.py", line 553, in create_engine
    entrypoint = u._get_entrypoint()
  File "/usr/local/lib/python3.13/site-packages/sqlalchemy/engine/url.py", line 772, in _get_entrypoint
    cls = registry.load(name)
  File "/usr/local/lib/python3.13/site-packages/sqlalchemy/util/langhelpers.py", line 375, in load
    raise exc.NoSuchModuleError(
        "Can't load plugin: %s:%s" % (self.group, name)
    )
sqlalchemy.exc.NoSuchModuleError: Can't load plugin: sqlalchemy.dialects:influxdb
2025-04-25 16:12:53.631 ERROR (Recorder) [homeassistant.components.recorder.core] Error during connection setup: (retrying in 3 seconds)
Traceback (most recent call last):
  File "/usr/src/homeassistant/homeassistant/components/recorder/core.py", line 927, in _setup_recorder
    self._setup_connection()
    ~~~~~~~~~~~~~~~~~~~~~~^^
  File "/usr/src/homeassistant/homeassistant/components/recorder/core.py", line 1437, in _setup_connection
    self.engine = create_engine(self.db_url, **kwargs, future=True)
                  ~~~~~~~~~~~~~^^^^^^^^^^^^^^^^^^^^^^^^^^^^^^^^^^^^
  File "<string>", line 2, in create_engine
  File "/usr/local/lib/python3.13/site-packages/sqlalchemy/util/deprecations.py", line 281, in warned
    return fn(*args, **kwargs)  # type: ignore[no-any-return]
  File "/usr/local/lib/python3.13/site-packages/sqlalchemy/engine/create.py", line 553, in create_engine
    entrypoint = u._get_entrypoint()
  File "/usr/local/lib/python3.13/site-packages/sqlalchemy/engine/url.py", line 772, in _get_entrypoint
    cls = registry.load(name)
  File "/usr/local/lib/python3.13/site-packages/sqlalchemy/util/langhelpers.py", line 375, in load
    raise exc.NoSuchModuleError(
        "Can't load plugin: %s:%s" % (self.group, name)
    )
sqlalchemy.exc.NoSuchModuleError: Can't load plugin: sqlalchemy.dialects:influxdb
2025-04-25 16:12:56.748 ERROR (Recorder) [homeassistant.components.recorder.core] Error during connection setup: (retrying in 3 seconds)
Traceback (most recent call last):
  File "/usr/src/homeassistant/homeassistant/components/recorder/core.py", line 927, in _setup_recorder
    self._setup_connection()
    ~~~~~~~~~~~~~~~~~~~~~~^^
  File "/usr/src/homeassistant/homeassistant/components/recorder/core.py", line 1437, in _setup_connection
    self.engine = create_engine(self.db_url, **kwargs, future=True)
                  ~~~~~~~~~~~~~^^^^^^^^^^^^^^^^^^^^^^^^^^^^^^^^^^^^
  File "<string>", line 2, in create_engine
  File "/usr/local/lib/python3.13/site-packages/sqlalchemy/util/deprecations.py", line 281, in warned
    return fn(*args, **kwargs)  # type: ignore[no-any-return]
  File "/usr/local/lib/python3.13/site-packages/sqlalchemy/engine/create.py", line 553, in create_engine
    entrypoint = u._get_entrypoint()
  File "/usr/local/lib/python3.13/site-packages/sqlalchemy/engine/url.py", line 772, in _get_entrypoint
    cls = registry.load(name)
  File "/usr/local/lib/python3.13/site-packages/sqlalchemy/util/langhelpers.py", line 375, in load
    raise exc.NoSuchModuleError(
        "Can't load plugin: %s:%s" % (self.group, name)
    )
sqlalchemy.exc.NoSuchModuleError: Can't load plugin: sqlalchemy.dialects:influxdb
2025-04-25 16:12:59.865 ERROR (Recorder) [homeassistant.components.recorder.core] Error during connection setup: (retrying in 3 seconds)
Traceback (most recent call last):
  File "/usr/src/homeassistant/homeassistant/components/recorder/core.py", line 927, in _setup_recorder
    self._setup_connection()
    ~~~~~~~~~~~~~~~~~~~~~~^^
  File "/usr/src/homeassistant/homeassistant/components/recorder/core.py", line 1437, in _setup_connection
    self.engine = create_engine(self.db_url, **kwargs, future=True)
                  ~~~~~~~~~~~~~^^^^^^^^^^^^^^^^^^^^^^^^^^^^^^^^^^^^
  File "<string>", line 2, in create_engine
  File "/usr/local/lib/python3.13/site-packages/sqlalchemy/util/deprecations.py", line 281, in warned
    return fn(*args, **kwargs)  # type: ignore[no-any-return]
  File "/usr/local/lib/python3.13/site-packages/sqlalchemy/engine/create.py", line 553, in create_engine
    entrypoint = u._get_entrypoint()
  File "/usr/local/lib/python3.13/site-packages/sqlalchemy/engine/url.py", line 772, in _get_entrypoint
    cls = registry.load(name)
  File "/usr/local/lib/python3.13/site-packages/sqlalchemy/util/langhelpers.py", line 375, in load
    raise exc.NoSuchModuleError(
        "Can't load plugin: %s:%s" % (self.group, name)
    )
sqlalchemy.exc.NoSuchModuleError: Can't load plugin: sqlalchemy.dialects:influxdb
2025-04-25 16:13:02.984 ERROR (Recorder) [homeassistant.components.recorder.core] Error during connection setup: (retrying in 3 seconds)
Traceback (most recent call last):
  File "/usr/src/homeassistant/homeassistant/components/recorder/core.py", line 927, in _setup_recorder
    self._setup_connection()
    ~~~~~~~~~~~~~~~~~~~~~~^^
  File "/usr/src/homeassistant/homeassistant/components/recorder/core.py", line 1437, in _setup_connection
    self.engine = create_engine(self.db_url, **kwargs, future=True)
                  ~~~~~~~~~~~~~^^^^^^^^^^^^^^^^^^^^^^^^^^^^^^^^^^^^
  File "<string>", line 2, in create_engine
  File "/usr/local/lib/python3.13/site-packages/sqlalchemy/util/deprecations.py", line 281, in warned
    return fn(*args, **kwargs)  # type: ignore[no-any-return]
  File "/usr/local/lib/python3.13/site-packages/sqlalchemy/engine/create.py", line 553, in create_engine
    entrypoint = u._get_entrypoint()
  File "/usr/local/lib/python3.13/site-packages/sqlalchemy/engine/url.py", line 772, in _get_entrypoint
    cls = registry.load(name)
  File "/usr/local/lib/python3.13/site-packages/sqlalchemy/util/langhelpers.py", line 375, in load
    raise exc.NoSuchModuleError(
        "Can't load plugin: %s:%s" % (self.group, name)
    )
sqlalchemy.exc.NoSuchModuleError: Can't load plugin: sqlalchemy.dialects:influxdb
2025-04-25 16:13:02.985 ERROR (Recorder) [homeassistant.components.recorder.core] Recorder setup failed, recorder shutting down
2025-04-25 16:13:02.986 ERROR (MainThread) [homeassistant.setup] Setup failed for 'recorder': Integration failed to initialize.
2025-04-25 16:13:04.414 ERROR (MainThread) [homeassistant.setup] Unable to set up dependencies of 'history'. Setup failed for dependencies: ['recorder']
2025-04-25 16:13:04.415 ERROR (MainThread) [homeassistant.setup] Setup failed for 'history': Could not setup dependencies: recorder
2025-04-25 16:13:04.420 ERROR (MainThread) [homeassistant.setup] Unable to set up dependencies of 'energy'. Setup failed for dependencies: ['history', 'recorder']
2025-04-25 16:13:04.420 ERROR (MainThread) [homeassistant.setup] Setup failed for 'energy': Could not setup dependencies: history, recorder
2025-04-25 16:13:04.435 ERROR (MainThread) [homeassistant.setup] Unable to set up dependencies of 'logbook'. Setup failed for dependencies: ['recorder']
2025-04-25 16:13:04.435 ERROR (MainThread) [homeassistant.setup] Setup failed for 'logbook': Could not setup dependencies: recorder
2025-04-25 16:13:06.819 ERROR (SyncWorker_2) [homeassistant.components.influxdb] Cannot connect to InfluxDB due to 'HTTPConnectionPool(host='influxdb.monitoring.svc.cluster.local', port=8086): Max retries exceeded with url: /write?db=home_assistant (Caused by NewConnectionError('<urllib3.connection.HTTPConnection object at 0x7dfcc940d1d0>: Failed to establish a new connection: [Errno -2] Name does not resolve'))'. Please check that the provided connection details (host, port, etc.) are correct and that your InfluxDB server is running and accessible. Retrying in 60 seconds.
2025-04-25 16:13:07.951 ERROR (MainThread) [homeassistant.setup] Unable to set up dependencies of 'default_config'. Setup failed for dependencies: ['energy', 'history', 'logbook']
2025-04-25 16:13:07.951 ERROR (MainThread) [homeassistant.setup] Setup failed for 'default_config': Could not setup dependencies: energy, history, logbook
2025-04-25 16:14:07.001 ERROR (SyncWorker_4) [homeassistant.components.influxdb] Cannot connect to InfluxDB due to 'HTTPConnectionPool(host='influxdb.monitoring.svc.cluster.local', port=8086): Max retries exceeded with url: /write?db=home_assistant (Caused by NewConnectionError('<urllib3.connection.HTTPConnection object at 0x7dfcc7071c70>: Failed to establish a new connection: [Errno -2] Name does not resolve'))'. Please check that the provided connection details (host, port, etc.) are correct and that your InfluxDB server is running and accessible. Retrying in 60 seconds.
