2025-04-26 07:31:51.075 ERROR (Recorder) [homeassistant.components.recorder.core] Error during connection setup: (retrying in 3 seconds)
Traceback (most recent call last):
  File "/usr/src/homeassistant/homeassistant/components/recorder/core.py", line 927, in _setup_recorder
    self._setup_connection()
    ~~~~~~~~~~~~~~~~~~~~~~^^
  File "/usr/src/homeassistant/homeassistant/components/recorder/core.py", line 1437, in _setup_connection
    self.engine = create_engine(self.db_url, **kwargs, future=True)
                  ~~~~~~~~~~~~~^^^^^^^^^^^^^^^^^^^^^^^^^^^^^^^^^^^^
  File "<string>", line 2, in create_engine
  File "/usr/local/lib/python3.13/site-packages/sqlalchemy/util/deprecations.py", line 281, in warned
    return fn(*args, **kwargs)  # type: ignore[no-any-return]
  File "/usr/local/lib/python3.13/site-packages/sqlalchemy/engine/create.py", line 553, in create_engine
    entrypoint = u._get_entrypoint()
  File "/usr/local/lib/python3.13/site-packages/sqlalchemy/engine/url.py", line 772, in _get_entrypoint
    cls = registry.load(name)
  File "/usr/local/lib/python3.13/site-packages/sqlalchemy/util/langhelpers.py", line 375, in load
    raise exc.NoSuchModuleError(
        "Can't load plugin: %s:%s" % (self.group, name)
    )
sqlalchemy.exc.NoSuchModuleError: Can't load plugin: sqlalchemy.dialects:influxdb
2025-04-26 07:31:54.219 ERROR (Recorder) [homeassistant.components.recorder.core] Error during connection setup: (retrying in 3 seconds)
Traceback (most recent call last):
  File "/usr/src/homeassistant/homeassistant/components/recorder/core.py", line 927, in _setup_recorder
    self._setup_connection()
    ~~~~~~~~~~~~~~~~~~~~~~^^
  File "/usr/src/homeassistant/homeassistant/components/recorder/core.py", line 1437, in _setup_connection
    self.engine = create_engine(self.db_url, **kwargs, future=True)
                  ~~~~~~~~~~~~~^^^^^^^^^^^^^^^^^^^^^^^^^^^^^^^^^^^^
  File "<string>", line 2, in create_engine
  File "/usr/local/lib/python3.13/site-packages/sqlalchemy/util/deprecations.py", line 281, in warned
    return fn(*args, **kwargs)  # type: ignore[no-any-return]
  File "/usr/local/lib/python3.13/site-packages/sqlalchemy/engine/create.py", line 553, in create_engine
    entrypoint = u._get_entrypoint()
  File "/usr/local/lib/python3.13/site-packages/sqlalchemy/engine/url.py", line 772, in _get_entrypoint
    cls = registry.load(name)
  File "/usr/local/lib/python3.13/site-packages/sqlalchemy/util/langhelpers.py", line 375, in load
    raise exc.NoSuchModuleError(
        "Can't load plugin: %s:%s" % (self.group, name)
    )
sqlalchemy.exc.NoSuchModuleError: Can't load plugin: sqlalchemy.dialects:influxdb
2025-04-26 07:31:57.348 ERROR (Recorder) [homeassistant.components.recorder.core] Error during connection setup: (retrying in 3 seconds)
Traceback (most recent call last):
  File "/usr/src/homeassistant/homeassistant/components/recorder/core.py", line 927, in _setup_recorder
    self._setup_connection()
    ~~~~~~~~~~~~~~~~~~~~~~^^
  File "/usr/src/homeassistant/homeassistant/components/recorder/core.py", line 1437, in _setup_connection
    self.engine = create_engine(self.db_url, **kwargs, future=True)
                  ~~~~~~~~~~~~~^^^^^^^^^^^^^^^^^^^^^^^^^^^^^^^^^^^^
  File "<string>", line 2, in create_engine
  File "/usr/local/lib/python3.13/site-packages/sqlalchemy/util/deprecations.py", line 281, in warned
    return fn(*args, **kwargs)  # type: ignore[no-any-return]
  File "/usr/local/lib/python3.13/site-packages/sqlalchemy/engine/create.py", line 553, in create_engine
    entrypoint = u._get_entrypoint()
  File "/usr/local/lib/python3.13/site-packages/sqlalchemy/engine/url.py", line 772, in _get_entrypoint
    cls = registry.load(name)
  File "/usr/local/lib/python3.13/site-packages/sqlalchemy/util/langhelpers.py", line 375, in load
    raise exc.NoSuchModuleError(
        "Can't load plugin: %s:%s" % (self.group, name)
    )
sqlalchemy.exc.NoSuchModuleError: Can't load plugin: sqlalchemy.dialects:influxdb
2025-04-26 07:32:00.476 ERROR (Recorder) [homeassistant.components.recorder.core] Error during connection setup: (retrying in 3 seconds)
Traceback (most recent call last):
  File "/usr/src/homeassistant/homeassistant/components/recorder/core.py", line 927, in _setup_recorder
    self._setup_connection()
    ~~~~~~~~~~~~~~~~~~~~~~^^
  File "/usr/src/homeassistant/homeassistant/components/recorder/core.py", line 1437, in _setup_connection
    self.engine = create_engine(self.db_url, **kwargs, future=True)
                  ~~~~~~~~~~~~~^^^^^^^^^^^^^^^^^^^^^^^^^^^^^^^^^^^^
  File "<string>", line 2, in create_engine
  File "/usr/local/lib/python3.13/site-packages/sqlalchemy/util/deprecations.py", line 281, in warned
    return fn(*args, **kwargs)  # type: ignore[no-any-return]
  File "/usr/local/lib/python3.13/site-packages/sqlalchemy/engine/create.py", line 553, in create_engine
    entrypoint = u._get_entrypoint()
  File "/usr/local/lib/python3.13/site-packages/sqlalchemy/engine/url.py", line 772, in _get_entrypoint
    cls = registry.load(name)
  File "/usr/local/lib/python3.13/site-packages/sqlalchemy/util/langhelpers.py", line 375, in load
    raise exc.NoSuchModuleError(
        "Can't load plugin: %s:%s" % (self.group, name)
    )
sqlalchemy.exc.NoSuchModuleError: Can't load plugin: sqlalchemy.dialects:influxdb
2025-04-26 07:32:00.552 WARNING (MainThread) [homeassistant.setup] Setup of recorder is taking over 10 seconds.
2025-04-26 07:32:03.600 ERROR (Recorder) [homeassistant.components.recorder.core] Error during connection setup: (retrying in 3 seconds)
Traceback (most recent call last):
  File "/usr/src/homeassistant/homeassistant/components/recorder/core.py", line 927, in _setup_recorder
    self._setup_connection()
    ~~~~~~~~~~~~~~~~~~~~~~^^
  File "/usr/src/homeassistant/homeassistant/components/recorder/core.py", line 1437, in _setup_connection
    self.engine = create_engine(self.db_url, **kwargs, future=True)
                  ~~~~~~~~~~~~~^^^^^^^^^^^^^^^^^^^^^^^^^^^^^^^^^^^^
  File "<string>", line 2, in create_engine
  File "/usr/local/lib/python3.13/site-packages/sqlalchemy/util/deprecations.py", line 281, in warned
    return fn(*args, **kwargs)  # type: ignore[no-any-return]
  File "/usr/local/lib/python3.13/site-packages/sqlalchemy/engine/create.py", line 553, in create_engine
    entrypoint = u._get_entrypoint()
  File "/usr/local/lib/python3.13/site-packages/sqlalchemy/engine/url.py", line 772, in _get_entrypoint
    cls = registry.load(name)
  File "/usr/local/lib/python3.13/site-packages/sqlalchemy/util/langhelpers.py", line 375, in load
    raise exc.NoSuchModuleError(
        "Can't load plugin: %s:%s" % (self.group, name)
    )
sqlalchemy.exc.NoSuchModuleError: Can't load plugin: sqlalchemy.dialects:influxdb
2025-04-26 07:32:06.724 ERROR (Recorder) [homeassistant.components.recorder.core] Error during connection setup: (retrying in 3 seconds)
Traceback (most recent call last):
  File "/usr/src/homeassistant/homeassistant/components/recorder/core.py", line 927, in _setup_recorder
    self._setup_connection()
    ~~~~~~~~~~~~~~~~~~~~~~^^
  File "/usr/src/homeassistant/homeassistant/components/recorder/core.py", line 1437, in _setup_connection
    self.engine = create_engine(self.db_url, **kwargs, future=True)
                  ~~~~~~~~~~~~~^^^^^^^^^^^^^^^^^^^^^^^^^^^^^^^^^^^^
  File "<string>", line 2, in create_engine
  File "/usr/local/lib/python3.13/site-packages/sqlalchemy/util/deprecations.py", line 281, in warned
    return fn(*args, **kwargs)  # type: ignore[no-any-return]
  File "/usr/local/lib/python3.13/site-packages/sqlalchemy/engine/create.py", line 553, in create_engine
    entrypoint = u._get_entrypoint()
  File "/usr/local/lib/python3.13/site-packages/sqlalchemy/engine/url.py", line 772, in _get_entrypoint
    cls = registry.load(name)
  File "/usr/local/lib/python3.13/site-packages/sqlalchemy/util/langhelpers.py", line 375, in load
    raise exc.NoSuchModuleError(
        "Can't load plugin: %s:%s" % (self.group, name)
    )
sqlalchemy.exc.NoSuchModuleError: Can't load plugin: sqlalchemy.dialects:influxdb
2025-04-26 07:32:09.851 ERROR (Recorder) [homeassistant.components.recorder.core] Error during connection setup: (retrying in 3 seconds)
Traceback (most recent call last):
  File "/usr/src/homeassistant/homeassistant/components/recorder/core.py", line 927, in _setup_recorder
    self._setup_connection()
    ~~~~~~~~~~~~~~~~~~~~~~^^
  File "/usr/src/homeassistant/homeassistant/components/recorder/core.py", line 1437, in _setup_connection
    self.engine = create_engine(self.db_url, **kwargs, future=True)
                  ~~~~~~~~~~~~~^^^^^^^^^^^^^^^^^^^^^^^^^^^^^^^^^^^^
  File "<string>", line 2, in create_engine
  File "/usr/local/lib/python3.13/site-packages/sqlalchemy/util/deprecations.py", line 281, in warned
    return fn(*args, **kwargs)  # type: ignore[no-any-return]
  File "/usr/local/lib/python3.13/site-packages/sqlalchemy/engine/create.py", line 553, in create_engine
    entrypoint = u._get_entrypoint()
  File "/usr/local/lib/python3.13/site-packages/sqlalchemy/engine/url.py", line 772, in _get_entrypoint
    cls = registry.load(name)
  File "/usr/local/lib/python3.13/site-packages/sqlalchemy/util/langhelpers.py", line 375, in load
    raise exc.NoSuchModuleError(
        "Can't load plugin: %s:%s" % (self.group, name)
    )
sqlalchemy.exc.NoSuchModuleError: Can't load plugin: sqlalchemy.dialects:influxdb
2025-04-26 07:32:12.975 ERROR (Recorder) [homeassistant.components.recorder.core] Error during connection setup: (retrying in 3 seconds)
Traceback (most recent call last):
  File "/usr/src/homeassistant/homeassistant/components/recorder/core.py", line 927, in _setup_recorder
    self._setup_connection()
    ~~~~~~~~~~~~~~~~~~~~~~^^
  File "/usr/src/homeassistant/homeassistant/components/recorder/core.py", line 1437, in _setup_connection
    self.engine = create_engine(self.db_url, **kwargs, future=True)
                  ~~~~~~~~~~~~~^^^^^^^^^^^^^^^^^^^^^^^^^^^^^^^^^^^^
  File "<string>", line 2, in create_engine
  File "/usr/local/lib/python3.13/site-packages/sqlalchemy/util/deprecations.py", line 281, in warned
    return fn(*args, **kwargs)  # type: ignore[no-any-return]
  File "/usr/local/lib/python3.13/site-packages/sqlalchemy/engine/create.py", line 553, in create_engine
    entrypoint = u._get_entrypoint()
  File "/usr/local/lib/python3.13/site-packages/sqlalchemy/engine/url.py", line 772, in _get_entrypoint
    cls = registry.load(name)
  File "/usr/local/lib/python3.13/site-packages/sqlalchemy/util/langhelpers.py", line 375, in load
    raise exc.NoSuchModuleError(
        "Can't load plugin: %s:%s" % (self.group, name)
    )
sqlalchemy.exc.NoSuchModuleError: Can't load plugin: sqlalchemy.dialects:influxdb
2025-04-26 07:32:16.098 ERROR (Recorder) [homeassistant.components.recorder.core] Error during connection setup: (retrying in 3 seconds)
Traceback (most recent call last):
  File "/usr/src/homeassistant/homeassistant/components/recorder/core.py", line 927, in _setup_recorder
    self._setup_connection()
    ~~~~~~~~~~~~~~~~~~~~~~^^
  File "/usr/src/homeassistant/homeassistant/components/recorder/core.py", line 1437, in _setup_connection
    self.engine = create_engine(self.db_url, **kwargs, future=True)
                  ~~~~~~~~~~~~~^^^^^^^^^^^^^^^^^^^^^^^^^^^^^^^^^^^^
  File "<string>", line 2, in create_engine
  File "/usr/local/lib/python3.13/site-packages/sqlalchemy/util/deprecations.py", line 281, in warned
    return fn(*args, **kwargs)  # type: ignore[no-any-return]
  File "/usr/local/lib/python3.13/site-packages/sqlalchemy/engine/create.py", line 553, in create_engine
    entrypoint = u._get_entrypoint()
  File "/usr/local/lib/python3.13/site-packages/sqlalchemy/engine/url.py", line 772, in _get_entrypoint
    cls = registry.load(name)
  File "/usr/local/lib/python3.13/site-packages/sqlalchemy/util/langhelpers.py", line 375, in load
    raise exc.NoSuchModuleError(
        "Can't load plugin: %s:%s" % (self.group, name)
    )
sqlalchemy.exc.NoSuchModuleError: Can't load plugin: sqlalchemy.dialects:influxdb
2025-04-26 07:32:19.225 ERROR (Recorder) [homeassistant.components.recorder.core] Error during connection setup: (retrying in 3 seconds)
Traceback (most recent call last):
  File "/usr/src/homeassistant/homeassistant/components/recorder/core.py", line 927, in _setup_recorder
    self._setup_connection()
    ~~~~~~~~~~~~~~~~~~~~~~^^
  File "/usr/src/homeassistant/homeassistant/components/recorder/core.py", line 1437, in _setup_connection
    self.engine = create_engine(self.db_url, **kwargs, future=True)
                  ~~~~~~~~~~~~~^^^^^^^^^^^^^^^^^^^^^^^^^^^^^^^^^^^^
  File "<string>", line 2, in create_engine
  File "/usr/local/lib/python3.13/site-packages/sqlalchemy/util/deprecations.py", line 281, in warned
    return fn(*args, **kwargs)  # type: ignore[no-any-return]
  File "/usr/local/lib/python3.13/site-packages/sqlalchemy/engine/create.py", line 553, in create_engine
    entrypoint = u._get_entrypoint()
  File "/usr/local/lib/python3.13/site-packages/sqlalchemy/engine/url.py", line 772, in _get_entrypoint
    cls = registry.load(name)
  File "/usr/local/lib/python3.13/site-packages/sqlalchemy/util/langhelpers.py", line 375, in load
    raise exc.NoSuchModuleError(
        "Can't load plugin: %s:%s" % (self.group, name)
    )
sqlalchemy.exc.NoSuchModuleError: Can't load plugin: sqlalchemy.dialects:influxdb
2025-04-26 07:32:19.226 ERROR (Recorder) [homeassistant.components.recorder.core] Recorder setup failed, recorder shutting down
2025-04-26 07:32:19.226 ERROR (MainThread) [homeassistant.setup] Setup failed for 'recorder': Integration failed to initialize.
2025-04-26 07:32:21.499 ERROR (MainThread) [homeassistant.setup] Unable to set up dependencies of 'history'. Setup failed for dependencies: ['recorder']
2025-04-26 07:32:21.499 ERROR (MainThread) [homeassistant.setup] Setup failed for 'history': Could not setup dependencies: recorder
2025-04-26 07:32:21.499 ERROR (MainThread) [homeassistant.setup] Unable to set up dependencies of 'energy'. Setup failed for dependencies: ['history', 'recorder']
2025-04-26 07:32:21.500 ERROR (MainThread) [homeassistant.setup] Setup failed for 'energy': Could not setup dependencies: history, recorder
2025-04-26 07:32:21.505 ERROR (MainThread) [homeassistant.setup] Unable to set up dependencies of 'logbook'. Setup failed for dependencies: ['recorder']
2025-04-26 07:32:21.506 ERROR (MainThread) [homeassistant.setup] Setup failed for 'logbook': Could not setup dependencies: recorder
2025-04-26 07:32:26.322 ERROR (MainThread) [homeassistant.setup] Unable to set up dependencies of 'default_config'. Setup failed for dependencies: ['energy', 'history', 'logbook']
2025-04-26 07:32:26.322 ERROR (MainThread) [homeassistant.setup] Setup failed for 'default_config': Could not setup dependencies: energy, history, logbook
2025-04-26 07:32:27.636 WARNING (MainThread) [homeassistant.config_entries] Config entry 'Kuba-Pospiesznywp.pl@wp.pl' for tuya integration could not authenticate: Authentication failed. Please re-authenticate
2025-04-26 07:32:38.647 WARNING (MainThread) [homeassistant.helpers.service] Referenced entities light.led_bulb_w509z2, light.lsc_smart_a60_rgb_cct, light.lsc_smart_a60_rgb_cct_2, light.lsc_smart_a60_rgb_cct_3 are missing or not currently available
