2025-04-25 16:17:49.850 ERROR (Recorder) [homeassistant.components.recorder.core] Error during connection setup: (retrying in 3 seconds)
Traceback (most recent call last):
  File "/usr/src/homeassistant/homeassistant/components/recorder/core.py", line 927, in _setup_recorder
    self._setup_connection()
    ~~~~~~~~~~~~~~~~~~~~~~^^
  File "/usr/src/homeassistant/homeassistant/components/recorder/core.py", line 1437, in _setup_connection
    self.engine = create_engine(self.db_url, **kwargs, future=True)
                  ~~~~~~~~~~~~~^^^^^^^^^^^^^^^^^^^^^^^^^^^^^^^^^^^^
  File "<string>", line 2, in create_engine
  File "/usr/local/lib/python3.13/site-packages/sqlalchemy/util/deprecations.py", line 281, in warned
    return fn(*args, **kwargs)  # type: ignore[no-any-return]
  File "/usr/local/lib/python3.13/site-packages/sqlalchemy/engine/create.py", line 553, in create_engine
    entrypoint = u._get_entrypoint()
  File "/usr/local/lib/python3.13/site-packages/sqlalchemy/engine/url.py", line 772, in _get_entrypoint
    cls = registry.load(name)
  File "/usr/local/lib/python3.13/site-packages/sqlalchemy/util/langhelpers.py", line 375, in load
    raise exc.NoSuchModuleError(
        "Can't load plugin: %s:%s" % (self.group, name)
    )
sqlalchemy.exc.NoSuchModuleError: Can't load plugin: sqlalchemy.dialects:influxdb
2025-04-25 16:17:52.978 ERROR (Recorder) [homeassistant.components.recorder.core] Error during connection setup: (retrying in 3 seconds)
Traceback (most recent call last):
  File "/usr/src/homeassistant/homeassistant/components/recorder/core.py", line 927, in _setup_recorder
    self._setup_connection()
    ~~~~~~~~~~~~~~~~~~~~~~^^
  File "/usr/src/homeassistant/homeassistant/components/recorder/core.py", line 1437, in _setup_connection
    self.engine = create_engine(self.db_url, **kwargs, future=True)
                  ~~~~~~~~~~~~~^^^^^^^^^^^^^^^^^^^^^^^^^^^^^^^^^^^^
  File "<string>", line 2, in create_engine
  File "/usr/local/lib/python3.13/site-packages/sqlalchemy/util/deprecations.py", line 281, in warned
    return fn(*args, **kwargs)  # type: ignore[no-any-return]
  File "/usr/local/lib/python3.13/site-packages/sqlalchemy/engine/create.py", line 553, in create_engine
    entrypoint = u._get_entrypoint()
  File "/usr/local/lib/python3.13/site-packages/sqlalchemy/engine/url.py", line 772, in _get_entrypoint
    cls = registry.load(name)
  File "/usr/local/lib/python3.13/site-packages/sqlalchemy/util/langhelpers.py", line 375, in load
    raise exc.NoSuchModuleError(
        "Can't load plugin: %s:%s" % (self.group, name)
    )
sqlalchemy.exc.NoSuchModuleError: Can't load plugin: sqlalchemy.dialects:influxdb
2025-04-25 16:17:56.095 ERROR (Recorder) [homeassistant.components.recorder.core] Error during connection setup: (retrying in 3 seconds)
Traceback (most recent call last):
  File "/usr/src/homeassistant/homeassistant/components/recorder/core.py", line 927, in _setup_recorder
    self._setup_connection()
    ~~~~~~~~~~~~~~~~~~~~~~^^
  File "/usr/src/homeassistant/homeassistant/components/recorder/core.py", line 1437, in _setup_connection
    self.engine = create_engine(self.db_url, **kwargs, future=True)
                  ~~~~~~~~~~~~~^^^^^^^^^^^^^^^^^^^^^^^^^^^^^^^^^^^^
  File "<string>", line 2, in create_engine
  File "/usr/local/lib/python3.13/site-packages/sqlalchemy/util/deprecations.py", line 281, in warned
    return fn(*args, **kwargs)  # type: ignore[no-any-return]
  File "/usr/local/lib/python3.13/site-packages/sqlalchemy/engine/create.py", line 553, in create_engine
    entrypoint = u._get_entrypoint()
  File "/usr/local/lib/python3.13/site-packages/sqlalchemy/engine/url.py", line 772, in _get_entrypoint
    cls = registry.load(name)
  File "/usr/local/lib/python3.13/site-packages/sqlalchemy/util/langhelpers.py", line 375, in load
    raise exc.NoSuchModuleError(
        "Can't load plugin: %s:%s" % (self.group, name)
    )
sqlalchemy.exc.NoSuchModuleError: Can't load plugin: sqlalchemy.dialects:influxdb
2025-04-25 16:17:59.212 ERROR (Recorder) [homeassistant.components.recorder.core] Error during connection setup: (retrying in 3 seconds)
Traceback (most recent call last):
  File "/usr/src/homeassistant/homeassistant/components/recorder/core.py", line 927, in _setup_recorder
    self._setup_connection()
    ~~~~~~~~~~~~~~~~~~~~~~^^
  File "/usr/src/homeassistant/homeassistant/components/recorder/core.py", line 1437, in _setup_connection
    self.engine = create_engine(self.db_url, **kwargs, future=True)
                  ~~~~~~~~~~~~~^^^^^^^^^^^^^^^^^^^^^^^^^^^^^^^^^^^^
  File "<string>", line 2, in create_engine
  File "/usr/local/lib/python3.13/site-packages/sqlalchemy/util/deprecations.py", line 281, in warned
    return fn(*args, **kwargs)  # type: ignore[no-any-return]
  File "/usr/local/lib/python3.13/site-packages/sqlalchemy/engine/create.py", line 553, in create_engine
    entrypoint = u._get_entrypoint()
  File "/usr/local/lib/python3.13/site-packages/sqlalchemy/engine/url.py", line 772, in _get_entrypoint
    cls = registry.load(name)
  File "/usr/local/lib/python3.13/site-packages/sqlalchemy/util/langhelpers.py", line 375, in load
    raise exc.NoSuchModuleError(
        "Can't load plugin: %s:%s" % (self.group, name)
    )
sqlalchemy.exc.NoSuchModuleError: Can't load plugin: sqlalchemy.dialects:influxdb
2025-04-25 16:17:59.679 WARNING (MainThread) [homeassistant.setup] Setup of recorder is taking over 10 seconds.
2025-04-25 16:18:02.331 ERROR (Recorder) [homeassistant.components.recorder.core] Error during connection setup: (retrying in 3 seconds)
Traceback (most recent call last):
  File "/usr/src/homeassistant/homeassistant/components/recorder/core.py", line 927, in _setup_recorder
    self._setup_connection()
    ~~~~~~~~~~~~~~~~~~~~~~^^
  File "/usr/src/homeassistant/homeassistant/components/recorder/core.py", line 1437, in _setup_connection
    self.engine = create_engine(self.db_url, **kwargs, future=True)
                  ~~~~~~~~~~~~~^^^^^^^^^^^^^^^^^^^^^^^^^^^^^^^^^^^^
  File "<string>", line 2, in create_engine
  File "/usr/local/lib/python3.13/site-packages/sqlalchemy/util/deprecations.py", line 281, in warned
    return fn(*args, **kwargs)  # type: ignore[no-any-return]
  File "/usr/local/lib/python3.13/site-packages/sqlalchemy/engine/create.py", line 553, in create_engine
    entrypoint = u._get_entrypoint()
  File "/usr/local/lib/python3.13/site-packages/sqlalchemy/engine/url.py", line 772, in _get_entrypoint
    cls = registry.load(name)
  File "/usr/local/lib/python3.13/site-packages/sqlalchemy/util/langhelpers.py", line 375, in load
    raise exc.NoSuchModuleError(
        "Can't load plugin: %s:%s" % (self.group, name)
    )
sqlalchemy.exc.NoSuchModuleError: Can't load plugin: sqlalchemy.dialects:influxdb
2025-04-25 16:18:05.452 ERROR (Recorder) [homeassistant.components.recorder.core] Error during connection setup: (retrying in 3 seconds)
Traceback (most recent call last):
  File "/usr/src/homeassistant/homeassistant/components/recorder/core.py", line 927, in _setup_recorder
    self._setup_connection()
    ~~~~~~~~~~~~~~~~~~~~~~^^
  File "/usr/src/homeassistant/homeassistant/components/recorder/core.py", line 1437, in _setup_connection
    self.engine = create_engine(self.db_url, **kwargs, future=True)
                  ~~~~~~~~~~~~~^^^^^^^^^^^^^^^^^^^^^^^^^^^^^^^^^^^^
  File "<string>", line 2, in create_engine
  File "/usr/local/lib/python3.13/site-packages/sqlalchemy/util/deprecations.py", line 281, in warned
    return fn(*args, **kwargs)  # type: ignore[no-any-return]
  File "/usr/local/lib/python3.13/site-packages/sqlalchemy/engine/create.py", line 553, in create_engine
    entrypoint = u._get_entrypoint()
  File "/usr/local/lib/python3.13/site-packages/sqlalchemy/engine/url.py", line 772, in _get_entrypoint
    cls = registry.load(name)
  File "/usr/local/lib/python3.13/site-packages/sqlalchemy/util/langhelpers.py", line 375, in load
    raise exc.NoSuchModuleError(
        "Can't load plugin: %s:%s" % (self.group, name)
    )
sqlalchemy.exc.NoSuchModuleError: Can't load plugin: sqlalchemy.dialects:influxdb
2025-04-25 16:18:08.568 ERROR (Recorder) [homeassistant.components.recorder.core] Error during connection setup: (retrying in 3 seconds)
Traceback (most recent call last):
  File "/usr/src/homeassistant/homeassistant/components/recorder/core.py", line 927, in _setup_recorder
    self._setup_connection()
    ~~~~~~~~~~~~~~~~~~~~~~^^
  File "/usr/src/homeassistant/homeassistant/components/recorder/core.py", line 1437, in _setup_connection
    self.engine = create_engine(self.db_url, **kwargs, future=True)
                  ~~~~~~~~~~~~~^^^^^^^^^^^^^^^^^^^^^^^^^^^^^^^^^^^^
  File "<string>", line 2, in create_engine
  File "/usr/local/lib/python3.13/site-packages/sqlalchemy/util/deprecations.py", line 281, in warned
    return fn(*args, **kwargs)  # type: ignore[no-any-return]
  File "/usr/local/lib/python3.13/site-packages/sqlalchemy/engine/create.py", line 553, in create_engine
    entrypoint = u._get_entrypoint()
  File "/usr/local/lib/python3.13/site-packages/sqlalchemy/engine/url.py", line 772, in _get_entrypoint
    cls = registry.load(name)
  File "/usr/local/lib/python3.13/site-packages/sqlalchemy/util/langhelpers.py", line 375, in load
    raise exc.NoSuchModuleError(
        "Can't load plugin: %s:%s" % (self.group, name)
    )
sqlalchemy.exc.NoSuchModuleError: Can't load plugin: sqlalchemy.dialects:influxdb
2025-04-25 16:18:11.684 ERROR (Recorder) [homeassistant.components.recorder.core] Error during connection setup: (retrying in 3 seconds)
Traceback (most recent call last):
  File "/usr/src/homeassistant/homeassistant/components/recorder/core.py", line 927, in _setup_recorder
    self._setup_connection()
    ~~~~~~~~~~~~~~~~~~~~~~^^
  File "/usr/src/homeassistant/homeassistant/components/recorder/core.py", line 1437, in _setup_connection
    self.engine = create_engine(self.db_url, **kwargs, future=True)
                  ~~~~~~~~~~~~~^^^^^^^^^^^^^^^^^^^^^^^^^^^^^^^^^^^^
  File "<string>", line 2, in create_engine
  File "/usr/local/lib/python3.13/site-packages/sqlalchemy/util/deprecations.py", line 281, in warned
    return fn(*args, **kwargs)  # type: ignore[no-any-return]
  File "/usr/local/lib/python3.13/site-packages/sqlalchemy/engine/create.py", line 553, in create_engine
    entrypoint = u._get_entrypoint()
  File "/usr/local/lib/python3.13/site-packages/sqlalchemy/engine/url.py", line 772, in _get_entrypoint
    cls = registry.load(name)
  File "/usr/local/lib/python3.13/site-packages/sqlalchemy/util/langhelpers.py", line 375, in load
    raise exc.NoSuchModuleError(
        "Can't load plugin: %s:%s" % (self.group, name)
    )
sqlalchemy.exc.NoSuchModuleError: Can't load plugin: sqlalchemy.dialects:influxdb
2025-04-25 16:18:14.803 ERROR (Recorder) [homeassistant.components.recorder.core] Error during connection setup: (retrying in 3 seconds)
Traceback (most recent call last):
  File "/usr/src/homeassistant/homeassistant/components/recorder/core.py", line 927, in _setup_recorder
    self._setup_connection()
    ~~~~~~~~~~~~~~~~~~~~~~^^
  File "/usr/src/homeassistant/homeassistant/components/recorder/core.py", line 1437, in _setup_connection
    self.engine = create_engine(self.db_url, **kwargs, future=True)
                  ~~~~~~~~~~~~~^^^^^^^^^^^^^^^^^^^^^^^^^^^^^^^^^^^^
  File "<string>", line 2, in create_engine
  File "/usr/local/lib/python3.13/site-packages/sqlalchemy/util/deprecations.py", line 281, in warned
    return fn(*args, **kwargs)  # type: ignore[no-any-return]
  File "/usr/local/lib/python3.13/site-packages/sqlalchemy/engine/create.py", line 553, in create_engine
    entrypoint = u._get_entrypoint()
  File "/usr/local/lib/python3.13/site-packages/sqlalchemy/engine/url.py", line 772, in _get_entrypoint
    cls = registry.load(name)
  File "/usr/local/lib/python3.13/site-packages/sqlalchemy/util/langhelpers.py", line 375, in load
    raise exc.NoSuchModuleError(
        "Can't load plugin: %s:%s" % (self.group, name)
    )
sqlalchemy.exc.NoSuchModuleError: Can't load plugin: sqlalchemy.dialects:influxdb
2025-04-25 16:18:17.920 ERROR (Recorder) [homeassistant.components.recorder.core] Error during connection setup: (retrying in 3 seconds)
Traceback (most recent call last):
  File "/usr/src/homeassistant/homeassistant/components/recorder/core.py", line 927, in _setup_recorder
    self._setup_connection()
    ~~~~~~~~~~~~~~~~~~~~~~^^
  File "/usr/src/homeassistant/homeassistant/components/recorder/core.py", line 1437, in _setup_connection
    self.engine = create_engine(self.db_url, **kwargs, future=True)
                  ~~~~~~~~~~~~~^^^^^^^^^^^^^^^^^^^^^^^^^^^^^^^^^^^^
  File "<string>", line 2, in create_engine
  File "/usr/local/lib/python3.13/site-packages/sqlalchemy/util/deprecations.py", line 281, in warned
    return fn(*args, **kwargs)  # type: ignore[no-any-return]
  File "/usr/local/lib/python3.13/site-packages/sqlalchemy/engine/create.py", line 553, in create_engine
    entrypoint = u._get_entrypoint()
  File "/usr/local/lib/python3.13/site-packages/sqlalchemy/engine/url.py", line 772, in _get_entrypoint
    cls = registry.load(name)
  File "/usr/local/lib/python3.13/site-packages/sqlalchemy/util/langhelpers.py", line 375, in load
    raise exc.NoSuchModuleError(
        "Can't load plugin: %s:%s" % (self.group, name)
    )
sqlalchemy.exc.NoSuchModuleError: Can't load plugin: sqlalchemy.dialects:influxdb
2025-04-25 16:18:17.921 ERROR (Recorder) [homeassistant.components.recorder.core] Recorder setup failed, recorder shutting down
2025-04-25 16:18:17.922 ERROR (MainThread) [homeassistant.setup] Setup failed for 'recorder': Integration failed to initialize.
2025-04-25 16:18:19.372 ERROR (MainThread) [homeassistant.setup] Unable to set up dependencies of 'history'. Setup failed for dependencies: ['recorder']
2025-04-25 16:18:19.372 ERROR (MainThread) [homeassistant.setup] Setup failed for 'history': Could not setup dependencies: recorder
2025-04-25 16:18:19.372 ERROR (MainThread) [homeassistant.setup] Unable to set up dependencies of 'energy'. Setup failed for dependencies: ['history', 'recorder']
2025-04-25 16:18:19.372 ERROR (MainThread) [homeassistant.setup] Setup failed for 'energy': Could not setup dependencies: history, recorder
2025-04-25 16:18:19.373 ERROR (MainThread) [homeassistant.setup] Unable to set up dependencies of 'logbook'. Setup failed for dependencies: ['recorder']
2025-04-25 16:18:19.373 ERROR (MainThread) [homeassistant.setup] Setup failed for 'logbook': Could not setup dependencies: recorder
2025-04-25 16:18:23.009 ERROR (MainThread) [homeassistant.setup] Unable to set up dependencies of 'default_config'. Setup failed for dependencies: ['energy', 'history', 'logbook']
2025-04-25 16:18:23.010 ERROR (MainThread) [homeassistant.setup] Setup failed for 'default_config': Could not setup dependencies: energy, history, logbook
