2025-04-25 13:54:00.230 ERROR (MainThread) [aiohttp.server] Error handling request from 10.42.0.1
Traceback (most recent call last):
  File "/usr/local/lib/python3.13/site-packages/aiohttp/web_protocol.py", line 480, in _handle_request
    resp = await request_handler(request)
           ^^^^^^^^^^^^^^^^^^^^^^^^^^^^^^
  File "/usr/local/lib/python3.13/site-packages/aiohttp/web_app.py", line 569, in _handle
    return await handler(request)
           ^^^^^^^^^^^^^^^^^^^^^^
  File "/usr/local/lib/python3.13/site-packages/aiohttp/web_middlewares.py", line 117, in impl
    return await handler(request)
           ^^^^^^^^^^^^^^^^^^^^^^
  File "/usr/src/homeassistant/homeassistant/components/http/security_filter.py", line 92, in security_filter_middleware
    return await handler(request)
           ^^^^^^^^^^^^^^^^^^^^^^
  File "/usr/src/homeassistant/homeassistant/components/http/forwarded.py", line 83, in forwarded_middleware
    return await handler(request)
           ^^^^^^^^^^^^^^^^^^^^^^
  File "/usr/src/homeassistant/homeassistant/components/http/request_context.py", line 26, in request_context_middleware
    return await handler(request)
           ^^^^^^^^^^^^^^^^^^^^^^
  File "/usr/src/homeassistant/homeassistant/components/http/ban.py", line 86, in ban_middleware
    return await handler(request)
           ^^^^^^^^^^^^^^^^^^^^^^
  File "/usr/src/homeassistant/homeassistant/components/http/auth.py", line 242, in auth_middleware
    return await handler(request)
           ^^^^^^^^^^^^^^^^^^^^^^
  File "/usr/src/homeassistant/homeassistant/components/http/headers.py", line 32, in headers_middleware
    response = await handler(request)
               ^^^^^^^^^^^^^^^^^^^^^^
  File "/usr/src/homeassistant/homeassistant/helpers/http.py", line 73, in handle
    result = await handler(request, **request.match_info)
             ^^^^^^^^^^^^^^^^^^^^^^^^^^^^^^^^^^^^^^^^^^^^
  File "/usr/src/homeassistant/homeassistant/components/http/data_validator.py", line 74, in wrapper
    return await method(view, request, data, *args, **kwargs)
           ^^^^^^^^^^^^^^^^^^^^^^^^^^^^^^^^^^^^^^^^^^^^^^^^^^
  File "/usr/src/homeassistant/homeassistant/components/onboarding/views.py", line 167, in post
    await provider.async_add_auth(data["username"], data["password"])
  File "/usr/src/homeassistant/homeassistant/auth/providers/homeassistant.py", line 328, in async_add_auth
    await self.hass.async_add_executor_job(self.data.add_auth, username, password)
  File "/usr/local/lib/python3.13/concurrent/futures/thread.py", line 59, in run
    result = self.fn(*self.args, **self.kwargs)
  File "/usr/src/homeassistant/homeassistant/auth/providers/homeassistant.py", line 198, in add_auth
    self._validate_new_username(username)
    ~~~~~~~~~~~~~~~~~~~~~~~~~~~^^^^^^^^^^
  File "/usr/src/homeassistant/homeassistant/auth/providers/homeassistant.py", line 247, in _validate_new_username
    raise InvalidUsername(
    ...<2 lines>...
    )
homeassistant.auth.providers.homeassistant.InvalidUsername: Username "Kobeep" is not normalized. Please make sure the username is lowercase and does not contain any whitespace
2025-04-25 13:54:20.228 WARNING (MainThread) [homeassistant.helpers.translation] Failed to load integration for translation: Invalid domain energy.sensor
2025-04-25 13:54:20.229 WARNING (MainThread) [homeassistant.helpers.translation] Failed to load integration for translation: Invalid domain cloud.tts
2025-04-25 13:54:20.229 WARNING (MainThread) [homeassistant.helpers.translation] Failed to load integration for translation: Invalid domain mobile_app.notify
2025-04-25 13:54:20.229 WARNING (MainThread) [homeassistant.helpers.translation] Failed to load integration for translation: Invalid domain backup.sensor
2025-04-25 13:54:20.229 WARNING (MainThread) [homeassistant.helpers.translation] Failed to load integration for translation: Invalid domain sun.sensor
2025-04-25 13:54:20.229 WARNING (MainThread) [homeassistant.helpers.translation] Failed to load integration for translation: Invalid domain homeassistant.scene
